(python-env) debian@debian:~/project1$ python3 main.py 
Getting all departments data
Getting section-list-INT database links
Getting section-list-SUG database links
Getting section-list-OBGYN database links
Getting section-list-PED database links
Getting section-list-TCM database links
Getting section-list-ENT database links
Getting section-list-DERM database links
Getting section-list-FM database links
Getting section-list-DEN database links
Getting section-list-OPH database links
Getting section-list-PSYCH database links
Getting section-list-NEURO database links
Getting section-list-REH database links
Getting section-list-COSMETIC database links
Getting section-list-MISC database links
Exception in thread Thread-4 (get_all_sections_database_link):
Traceback (most recent call last):
  File "/usr/lib/python3.11/threading.py", line 1038, in _bootstrap_inner
    self.run()
  File "/usr/lib/python3.11/threading.py", line 975, in run
    self._target(*self._args, **self._kwargs)
  File "/home/debian/project1/department_handle.py", line 105, in get_all_sections_database_link
    self.driver.get(f'{url}{section.link}')
  File "/home/debian/project1/python-env/lib/python3.11/site-packages/selenium/webdriver/remote/webdriver.py", line 356, in get
    self.execute(Command.GET, {"url": url})
  File "/home/debian/project1/python-env/lib/python3.11/site-packages/selenium/webdriver/remote/webdriver.py", line 347, in execute
    self.error_handler.check_response(response)
  File "/home/debian/project1/python-env/lib/python3.11/site-packages/selenium/webdriver/remote/errorhandler.py", line 229, in check_response
    raise exception_class(message, screen, stacktrace)
selenium.common.exceptions.TimeoutException: Message: timeout: Timed out receiving message from renderer: 299.376
  (Session info: chrome=124.0.6367.155)
Stacktrace:
#0 0x55940dbe2df3 <unknown>
#1 0x55940d8d14e7 <unknown>
#2 0x55940d8b93bd <unknown>
#3 0x55940d8b90d3 <unknown>
#4 0x55940d8b705c <unknown>
#5 0x55940d8b76ef <unknown>
#6 0x55940d8c7c81 <unknown>
#7 0x55940d8dd26e <unknown>
#8 0x55940d8e287b <unknown>
#9 0x55940d8b7e32 <unknown>
#10 0x55940d8dcfe5 <unknown>
#11 0x55940d95cf83 <unknown>
#12 0x55940d93e1f3 <unknown>
#13 0x55940d90f28a <unknown>
#14 0x55940d90fc5e <unknown>
#15 0x55940dba711b <unknown>
#16 0x55940dbab06b <unknown>
#17 0x55940db93231 <unknown>
#18 0x55940dbabbd2 <unknown>
#19 0x55940db780ef <unknown>
#20 0x55940dbd1f48 <unknown>
#21 0x55940dbd2120 <unknown>
#22 0x55940dbe1f44 <unknown>
#23 0x7f47bbc8b134 <unknown>

Getting section-list-INT - section-1 Q&A
Exception in thread Thread-16 (get_q_and_a):
Traceback (most recent call last):
  File "/usr/lib/python3.11/threading.py", line 1038, in _bootstrap_inner
    self.run()
  File "/usr/lib/python3.11/threading.py", line 975, in run
    self._target(*self._args, **self._kwargs)
  File "/home/debian/project1/database_handle.py", line 128, in get_q_and_a
    q_and_a = question_handler(question_link).get_q_and_a()
              ^^^^^^^^^^^^^^^^^^^^^^^^^^^^^^^^^^^^^^^^^^^^^
  File "/home/debian/project1/database_handle.py", line 40, in get_q_and_a
    question = self.__get_question()
               ^^^^^^^^^^^^^^^^^^^^^
  File "/home/debian/project1/database_handle.py", line 26, in __get_question
    question_div = question_date.find_parent().find(text=True, recursive=False)
                   ^^^^^^^^^^^^^^^^^^^^^^^^^
AttributeError: 'NoneType' object has no attribute 'find_parent'
^CTraceback (most recent call last):
  File "/home/debian/project1/main.py", line 76, in <module>
    main()
  File "/home/debian/project1/main.py", line 65, in main
    semaphore.acquire()
  File "/usr/lib/python3.11/threading.py", line 472, in acquire
    self._cond.wait(timeout)
  File "/usr/lib/python3.11/threading.py", line 320, in wait
    waiter.acquire()
KeyboardInterrupt

(python-env) debian@debian:~/project1$ 
